Workbook

Sheet IPTV US
A1: Channel Number | B1: Channel Name | C1: Provider | D1: Availability | E1: Rovi 1.1 Source ID | F1: Rovi 2.0 Source ID | G1: Partner Station Id | H1: playbackUrlChannelId | I1: channelChangeId | J1: Call Sign | K1: Packaged Service Description | L1: XUMO playURL (Pre-Frumos 1.20) | M1: XUMO playURL (Frumos 1.20) | N1: Packaged Service Id | O1: TiVo+ Genre | P1: IPTV Platform (mATV) | Q1: IPTV Unmanaged Streaming Devices
A2: 10101 | B2: CNN Headlines | C2: Pluto TV | D2: Live | E2: 100371 | F2: 9010079773 | G2: 427517053 | H2: cnn-headlines | I2: 5421f71da6af422839419cb3 | J2: CNNHEADLINES | K2: CNN Headlines | N2: 427517053 | O2: News & Opinion | P2: ✔
A3: 10102 | B3: NBC News Now | C3: Pluto TV | D3: Live | E3: 100582 | F3: 9192516135 | G3: 429861982 | H3: nbc-news-now | I3: 5df97894467dfa00091c873c | J3: NBCNNW | K3: NBC News Now | N3: 429861982 | O3: News & Opinion | P3: ✔
A4: 10103 | C4: Pluto TV
A5: 10104 | B5: CBS News 24/7 | C5: Pluto TV | D5: Live | E5: 100432 | F5: 9010105410 | G5: 427517050 | H5: cbs-news | I5: 5a6b92f6e22a617379789618 | J5: CBSNEWS-TIVO | K5: CBS News 24/7 | N5: 427517050 | O5: News & Opinion | P5: ✔
A6: 10105 | C6: Pluto TV
A7: 10106 | C7: Pluto TV
A8: 10107 | C8: Pluto TV
A9: 10108 | C9: Pluto TV
A10: 10109 | C10: Pluto TV
A11: 10110 | C11: Pluto TV
A12: 10111 | B12: Sky News | C12: Pluto TV | D12: Live | E12: 100417 | F12: 9010098841 | G12: 427517061 | H12: sky-news | I12: 55b285cd2665de274553d66f | J12: SKYNEW | K12: Sky News | N12: 427517061 | O12: News & Opinion | P12: ✔
A13: 10112 | B13: Blaze Live | C13: Pluto TV | D13: Live | E13: 37159 | F13: 312864873 | G13: 235665557 | H13: blaze-live | I13: 5e46fba0c43b0d00096e5ac1 | J13: BLAZESD | K13: Blaze Live | N13: 235665557 | O13: News & Opinion | P13: ✔
A14: 10113 | C14: Pluto TV
A15: 10114 | C15: Pluto TV
A16: 10115 | C16: Pluto TV
A17: 10116 | C17: Pluto TV
A18: 10117 | B18: Pluto TV Crime Movies | C18: Pluto TV | D18: Live | E18: 109771 | F18: 14580966827 | G18: 499315358 | H18: pluto-tv-crime-movies | I18: 5f4d8594eb979c0007706de7 | J18: CRMOVPLUTO | K18: Pluto TV Crime Movies | N18: 499315358 | O18: Movies | P18: ✔
A19: 10118 | B19: Pluto TV Westerns | C19: Pluto TV | D19: Live | E19: 100370 | F19: 9010079772 | G19: 427517072 | H19: pluto-tv-westerns-ptv1 | I19: 5b4e94282d4ec87bdcbb87cd | J19: PLUWEST | K19: Pluto TV Westerns | N19: 427517072 | O19: Movies | P19: ✔
A20: 10119 | B20: Pluto TV Action | C20: Pluto TV | D20: Live | E20: 100400 | F20: 9010089140 | G20: 427517024 | H20: pluto-tv-action | I20: 561d7d484dc7c8770484914a | J20: PLUTOACT | K20: Pluto TV Action | N20: 427517024 | O20: Movies | P20: ✔
A21: 10120 | B21: Black Cinema | C21: Pluto TV | D21: Live | E21: 100364 | F21: 9010077077 | G21: 427517054 | H21: black-cinema | I21: 58af4c093a41ca9d4ecabe96 | J21: BLAKCINE | K21: Black Cinema | N21: 427517054 | O21: Movies | P21: ✔
A22: 10121 | B22: Pluto TV Horror | C22: Pluto TV | D22: Live | E22: 100408 | F22: 9010092582 | G22: 427517034 | H22: pluto-tv-horror | I22: 569546031a619b8f07ce6e25 | J22: PLUTVHOR | K22: Pluto TV Horror | N22: 427517034 | O22: Movies | P22: ✔
A23: 10122 | B23: Pluto TV Terror | C23: Pluto TV | D23: Live | E23: 100416 | F23: 9010098708 | G23: 427517019 | H23: pluto-tv-terror | I23: 5c6dc88fcd232425a6e0f06e | J23: PLUTVTER | K23: Pluto TV Terror | N23: 427517019 | O23: Movies | P23: ✔
A24: 10123 | B24: Pluto TV Sci-Fi | C24: Pluto TV | D24: Live | E24: 100413 | F24: 9010096138 | G24: 427517067 | H24: pluto-tv-sci-fi | I24: 5b4fc274694c027be6ed3eea | J24: PLUTVSCI | K24: Pluto TV Sci-Fi | N24: 427517067 | O24: Movies | P24: ✔
A25: 10124 | B25: Pluto TV Comedy | C25: Pluto TV | D25: Live | E25: 100405 | F25: 9010089821 | G25: 427517068 | H25: pluto-tv-comedy | I25: 5a4d3a00ad95e4718ae8d8db | J25: PLUTVCOM | K25: Pluto TV Comedy | N25: 427517068 | O25: Movies | P25: ✔
A26: 10125 | B26: Pluto TV Drama | C26: Pluto TV | D26: Live | E26: 100406 | F26: 9010092184 | G26: 427517040 | H26: pluto-tv-drama | I26: 5b4e92e4694c027be6ecece1 | J26: PLUTVDRA | K26: Pluto TV Drama | N26: 427517040 | O26: Movies | P26: ✔
A27: 10126 | B27: Pluto TV Fantastic | C27: Pluto TV | D27: Live | E27: 100407 | F27: 9010092350 | G27: 427517073 | H27: pluto-tv-fantastic | I27: 5b64a245a202b3337f09e51d | J27: PLUTVFAN | K27: Pluto TV Fantastic | N27: 427517073 | O27: Movies | P27: ✔
A28: 10127 | C28: Pluto TV
A29: 10128 | B29: Pluto TV Romance | C29: Pluto TV | D29: Live | E29: 100412 | F29: 9010094694 | G29: 427571159 | H29: pluto-tv-romance | I29: 5a66795ef91fef2c7031c599 | J29: PLURVROM | K29: Pluto TV Romance | N29: 427571159 | O29: Movies | P29: ✔
A30: 10129 | B30: Pluto TV Spotlight | C30: Pluto TV | D30: Live | E30: 100414 | F30: 9010098650 | G30: 427517026 | H30: pluto-tv-spotlight | I30: 5ba3fb9c4b078e0f37ad34e8 | J30: PLUTVSP | K30: Pluto TV Spotlight | N30: 427517026 | O30: Movies | P30: ✔
A31: 10130 | B31: Paramount Movie Channel | C31: Pluto TV | D31: Live | E31: 100399 | F31: 9010089139 | G31: 427517006 | H31: paramount-movie-channel | I31: 5cb0cae7a461406ffe3f5213 | J31: PARAMOVC | K31: Paramount Movie Channel | N31: 427517006 | O31: Movies | P31: ✔
A32: 10131 | B32: 70's Cinema | C32: Pluto TV | D32: Live | E32: 101607 | F32: 10158522042 | G32: 442803426 | H32: 70s-cinema | I32: 5f4d878d3d19b30007d2e782 | J32: 70CINEMA | K32: 70's Cinema | N32: 442803426 | O32: Movies | P32: ✔
A33: 10132 | B33: 80's Rewind | C33: Pluto TV | D33: Live | E33: 101606 | F33: 10158517642 | G33: 442803415 | H33: 80s-rewind | I33: 5ca525b650be2571e3943c63 | J33: 80REWIND | K33: 80's Rewind | N33: 442803415 | O33: Movies | P33: ✔
A34: 10133 | B34: 90's Throwback | C34: Pluto TV | D34: Live | E34: 101605 | F34: 10157721666 | G34: 442803411 | H34: 90s-throwback | I34: 5f4d86f519358a00072b978e | J34: 90THROW | K34: 90's Throwback | N34: 442803411 | O34: Movies | P34: ✔
A35: 10134 | C35: Pluto TV
A36: 10135 | C36: Pluto TV
A37: 10136 | C37: Pluto TV
A38: 10137 | C38: Pluto TV
A39: 10138 | B39: COPS | C39: Pluto TV | D39: Live | E39: 100375 | F39: 9010081021 | G39: 427517066 | H39: cops | I39: 5e1f7e089f23700009d66303 | J39: COPS | K39: COPS | N39: 427517066 | O39: True Crime | P39: ✔
A40: 10139 | B40: Forensic Files | C40: Pluto TV | D40: Live | E40: 100380 | F40: 9010083617 | G40: 427517014 | H40: forensic-files | I40: 5bb1af6a268cae539bcedb0a | J40: FORFILE | K40: Forensic Files | N40: 427517014 | O40: True Crime | P40: ✔
...

Sheet IPTV CA
A1: Channel Number | B1: Channel Name | C1: Provider | D1: Availability | E1: Rovi 1.1 Source ID | F1: Rovi 2.0 Source ID | G1: Partner Station Id | H1: playbackUrlChannelId | I1: channelChangeId | J1: Call Sign | K1: Packaged Service Description | L1: XUMO playURL (Pre-Frumos 1.20) | M1: XUMO playURL (Frumos 1.20) | N1: Packaged Service Id | O1: TiVo+ Genre | P1: IPTV Platform (mATV) | Q1: IPTV Unmanaged Streaming Devices
A2: 10401 | B2: Bloomberg TV | C2: Direct | D2: Live | E2: 113171 | F2: 16354099306 | G2: 521876205 | J2: BLTVXUMO | K2: Direct-Bloomberg TV | M2: https:TIVOPLUS_BLANK//dai.google.com/linear/hls/event/AshzBu9XTQScek7dcLQlCA/master.m3u8?devid=TIVOPLUS_DEV_ID&devlat=TIVOPLUS_DEV_LAT&gdprconsent=&platform=TIVOPLUS_PLATFORM | N2: 99000000 | P2: ✔
A3: 10402 | B3: Bloomberg Originals | C3: Direct | D3: Live | E3: 113170 | F3: 16354087548 | G3: 521876204 | J3: BLORXUM | K3: Direct-Bloomberg Originals | M3: https:TIVOPLUS_BLANK//dai.google.com/linear/hls/event/TgqE2Aw_SiKmXKQgJoVpJQ/master.m3u8?devid=TIVOPLUS_DEV_ID&devlat=TIVOPLUS_DEV_LAT&gdprconsent=&platform=TIVOPLUS_PLATFORM | N3: 99000001 | P3: ✔
A4: 10403 | C4: XUMO
A5: 10404 | C5: XUMO
A6: 10405 | C6: XUMO
A7: 10406 | B7: Filmrise Canadien | C7: XUMO | D7: Live | E7: 111974 | F7: 15836602686 | G7: 515581920 | J7: FLMRCAXU | K7: XUMO-Filmrise Canadien | M7: https:TIVOPLUS_BLANK//db32be3yl2hko.cloudfront.net/11302/88885125/hls/master.m3u8?ads.xumo_channelId=88885125&ads.caid=FilmRiseCA&ads.csid=tivo_ca_filmrisecanadien_ssai&ads.coppa=0&ads.provider_id=1082&ads.content_producer_id=1082&ads.content_producer=FilmRiseCA&ads.content_network=FilmRiseCA&ads.xumo_streamId=88885125&ads.content_length=&ads.content_language=en&ads.content_category=IAB1-7&ads.content_genre=Television&ads.content_rating=tv14&&ads.content_channel=FilmriseCanadien&ads.app_name=TIVOPLUS_APPNAME&ads.app_version=TIVOPLUS_APP_VERSION&ads.app_bundle=tivo.entertainment&ads.did=TIVOPLUS_DEV_ID&ads.did_type=TIVOPLUS_DEV_TYPE&ads.is_lat=TIVOPLUS_DEV_LAT&ads.us_privacy=TIVOPLUS_USPRIVACY&ads.gdpr=&ads.gdpr_consent=&ads.app_domain=tivo.com&ads.device_type=TIVOPLUS_OPENRTB_DEVTYPE&ads.app_store_url=&ads.tivo_kvps=partnername%253DXumo%2526mvpd%253DTIVOPLUS_MVPD%2526adunittype%253DTIVOPLUS_ADUNIT_TYPE%2526sz%253D1920x1080%2526contenttype%253DLinear%2526uxloc%253DInapp%2526apptype%253DEntertainment%2526videotype%253Dmidroll%2526devcountry%253D%2526usid%253DTIVOPLUS_USERSESSION_ID%2526devlang%253D%2526platform%253DTIVOPLUS_PLATFORM%2526devmake%253DTIVOPLUS_DEVMAKE%2526devbrand%253D%2526devmake%253DTIVOPLUS_DEVMODEL%2526devmakedate%253D%2526devbrand%253D%2526devmake%253DTIVOPLUS_DEVMODEL%2526devmakedate%253D") | N7: 99000002 | P7: ✔
A8: 10407 | C8: XUMO
A9: 10408 | C9: XUMO
A10: 10409 | C10: XUMO
A11: 10410 | C11: XUMO
A12: 10411 | B12: FilmRise Western | C12: XUMO | D12: Live | E12: 111975 | F12: 15836608730 | G12: 515581901 | J12: FRISEXU | K12: XUMO-FilmRise Western | M12: https:TIVOPLUS_BLANK//db32be3yl2hko.cloudfront.net/11302/88885127/hls/master.m3u8?ads.xumo_channelId=88885127&ads.caid=FilmRise&ads.csid=tivo_us_filmrisewestern_ssai&ads.coppa=0&ads.provider_id=260&ads.content_producer_id=260&ads.content_producer=FilmRise&ads.content_network=FilmRise&ads.xumo_streamId=88885127&ads.content_length=&ads.content_language=en&ads.content_category=IAB17&ads.content_genre=Television&ads.content_rating=tvpg&ads.content_channel=FilmriseWestern&ads.app_name=TIVOPLUS_APPNAME&ads.app_version=TIVOPLUS_APP_VERSION&ads.app_bundle=tivo.entertainment&ads.did=TIVOPLUS_DEV_ID&ads.did_type=TIVOPLUS_DEV_TYPE&ads.is_lat=TIVOPLUS_DEV_LAT&ads.us_privacy=TIVOPLUS_USPRIVACY&ads.gdpr=&ads.gdpr_consent=&ads.app_domain=tivo.com&ads.device_type=TIVOPLUS_OPENRTB_DEVTYPE&ads.app_store_url=&ads.tivo_kvps=partnername%253DXumo%2526mvpd%253DTIVOPLUS_MVPD%2526adunittype%253DTIVOPLUS_ADUNIT_TYPE%2526sz%253D1920x1080%2526contenttype%253DLinear%2526uxloc%253DIn-app%2526apptype%253DEntertainment%2526videotype%253Dmid-roll%2526devcountry%253D%2526usid%253DTIVOPLUS_USERSESSION_ID%2526devlang%253D%2526platform%253DTIVOPLUS_PLATFORM%2526devmake%253DTIVOPLUS_DEVMAKE%2526devbrand%253D%2526devmake%253DTIVOPLUS_DEVMODEL%2526devmakedate%253D | N12: 99000003 | P12: ✔
A13: 10412 | C13: XUMO
A14: 10413 | C14: XUMO
A15: 10414 | C15: XUMO
A16: 10415 | C16: XUMO
A17: 10416 | C17: XUMO
A18: 10417 | B18: Shades of Black | C18: XUMO | D18: Live | E18: 112551 | F18: 16106044260 | G18: 519562724 | J18: SHADBLKXU-CA | K18: XUMO-Shades of Black | M18: https:TIVOPLUS_BLANK//db32be3yl2hko.cloudfront.net/11302/88885139/hls/playlist.m3u8?ads.xumo_channelId=88885139&ads.caid=FuseShadesofBlackCanada&ads.csid=tivo_ca_fuseshadesofblackcanada_ssai&ads.coppa=0&ads.provider_id=4032&ads.content_producer_id=4032&ads.content_producer=FuseShadesofBlackCanada&ads.content_network=FuseShadesofBlackCanada&ads.xumo_streamId=88885139&ads.content_length=&ads.content_language=en&ads.content_category=IAB1-7&ads.content_genre=Television&ads.content_rating=tv-14&ads.content_channel=ShadesofBlackCanada&ads.app_name=TIVOPLUS_APPNAME&ads.app_version=TIVOPLUS_APP_VERSION&ads.app_bundle=tivo.entertainment&ads.did=TIVOPLUS_DEV_ID&ads.did_type=TIVOPLUS_DEV_TYPE&ads.is_lat=TIVOPLUS_DEV_LAT&ads.us_privacy=TIVOPLUS_USPRIVACY&ads.gdpr=&ads.gdpr_consent=&ads.app_domain=tivo.com&ads.device_type=TIVOPLUS_OPENRTB_DEVTYPE&ads.app_store_url=&ads.tivo_kvps=partnername%253DXumo%2526mvpd%253DTIVOPLUS_MVPD%2526adunittype%253DTIVOPLUS_ADUNIT_TYPE%2526sz%253D1920x1080%2526contenttype%253DLinear%2526uxloc%253DIn-app%2526apptype%253DEntertainment%2526videotype%253Dmid-roll%2526devcountry%253D%2526usid%253DTIVOPLUS_USERSESSION_ID%2526devlang%253D%2526platform%253DTIVOPLUS_PLATFORM%2526devmake%253DTIVOPLUS_DEVMAKE%2526devbrand%253D%2526devmake%253DTIVOPLUS_DEVMODEL%2526devmakedate%253D | N18: 99000004 | P18: ✔
A19: 10418 | B19: OUTtv Proud | C19: XUMO | D19: Live | E19: 112549 | F19: 16106021655 | G19: 519562723 | J19: OUTTVPRDXUMO | K19: XUMO-OUTtv Proud | M19: https:TIVOPLUS_BLANK//db32be3yl2hko.cloudfront.net/11302/88885137/hls/playlist.m3u8?ads.xumo_channelId=88885137&ads.caid=FuseOutTVProud&ads.csid=tivo_us_fuseouttvproud_ssai&ads.coppa=0&ads.provider_id=4004&ads.content_producer_id=4004&ads.content_producer=FuseOutTVProud&ads.content_network=FuseOutTVProud&ads.xumo_streamId=88885137&ads.content_length=&ads.content_language=en&ads.content_category=IAB1-7&ads.content_genre=Television&ads.content_rating=tv-14&ads.content_channel=OutTVProud&ads.app_name=TIVOPLUS_APPNAME&ads.app_version=TIVOPLUS_APP_VERSION&ads.app_bundle=tivo.entertainment&ads.did=TIVOPLUS_DEV_ID&ads.did_type=TIVOPLUS_DEV_TYPE&ads.is_lat=TIVOPLUS_DEV_LAT&ads.us_privacy=TIVOPLUS_USPRIVACY&ads.gdpr=&ads.gdpr_consent=&ads.app_domain=tivo.com&ads.device_type=TIVOPLUS_OPENRTB_DEVTYPE&ads.app_store_url=&ads.tivo_kvps=partnername%253DXumo%2526mvpd%253DTIVOPLUS_MVPD%2526adunittype%253DTIVOPLUS_ADUNIT_TYPE%2526sz%253D1920x1080%2526contenttype%253DLinear%2526uxloc%253DIn-app%2526apptype%253DEntertainment%2526videotype%253Dmid-roll%2526devcountry%253D%2526usid%253DTIVOPLUS_USERSESSION_ID%2526devlang%253D%2526platform%253DTIVOPLUS_PLATFORM%2526devmake%253DTIVOPLUS_DEVMAKE%2526devbrand%253D%2526devmake%253DTIVOPLUS_DEVMODEL%2526devmakedate%253D | N19: 99000005 | P19: ✔
A20: 10419 | C20: XUMO
A21: 10420 | C21: XUMO
A22: 10421 | C22: XUMO
A23: 10422 | C23: XUMO
A24: 10423 | C24: XUMO
A25: 10424 | B25: Filmrise Classic TV | C25: XUMO | D25: Live | E25: 109841 | F25: 14663826120 | G25: 500453464 | J25: FILMRASXU | K25: XUMO-Filmrise Classic TV | M25: https:TIVOPLUS_BLANK//db32be3yl2hko.cloudfront.net/11302/88885126/hls/master.m3u8?ads.xumo_channelId=88885126&ads.caid=FilmRiseCA&ads.csid=tivo_ca_filmriseclassictv_ssai&ads.coppa=0&ads.provider_id=1082&ads.content_producer_id=1082&ads.content_producer=FilmRiseCA&ads.content_network=FilmRiseCA&ads.xumo_streamId=88885126&ads.content_length=&ads.content_language=en&ads.content_category=IAB1-7&ads.content_genre=Television&ads.content_rating=tvpg&ads.content_channel=FilmriseClassicTV&ads.app_name=TIVOPLUS_APPNAME&ads.app_version=TIVOPLUS_APP_VERSION&ads.app_bundle=tivo.entertainment&ads.did=TIVOPLUS_DEV_ID&ads.did_type=TIVOPLUS_DEV_TYPE&ads.is_lat=TIVOPLUS_DEV_LAT&ads.us_privacy=TIVOPLUS_USPRIVACY&ads.gdpr=&ads.gdpr_consent=&ads.app_domain=tivo.com&ads.device_type=TIVOPLUS_OPENRTB_DEVTYPE&ads.app_store_url=&ads.tivo_kvps=partnername%253DXumo%2526mvpd%253DTIVOPLUS_MVPD%2526adunittype%253DTIVOPLUS_ADUNIT_TYPE%2526sz%253D1920x1080%2526contenttype%253DLinear%2526uxloc%253DIn-app%2526apptype%253DEntertainment%2526videotype%253Dmidroll%2526devcountry%253D%2526usid%253DTIVOPLUS_USERSESSION_ID%2526devlang%253D%2526platform%253DTIVOPLUS_PLATFORM%2526devmake%253DTIVOPLUS_DEVMAKE%2526devbrand%253D%2526devmake%253DTIVOPLUS_DEVMODEL%2526devmakedate%253D") | N25: 99000006 | P25: ✔
A26: 10425 | B26: Hell’s Kitchen | C26: XUMO | D26: Live | E26: 111978 | F26: 15836622952 | G26: 515581914 | J26: HELLKXU | K26: XUMO-Hell’s Kitchen | M26: https:TIVOPLUS_BLANK//db32be3yl2hko.cloudfront.net/11302/88885129/hls/master.m3u8?ads.xumo_channelId=88885129&ads.caid=FilmRise&ads.csid=tivo_us_hellskitchen_ssai&ads.coppa=0&ads.provider_id=260&ads.content_producer_id=260&ads.content_producer=FilmRise&ads.content_network=FilmRise&ads.xumo_streamId=88885129&ads.content_length=&ads.content_language=en&ads.content_category=IAB17&ads.content_genre=Television&ads.content_rating=tv14&ads.content_channel=HellsKitchen&ads.app_name=TIVOPLUS_APPNAME&ads.app_version=TIVOPLUS_APP_VERSION&ads.app_bundle=tivo.entertainment&ads.did=TIVOPLUS_DEV_ID&ads.did_type=TIVOPLUS_DEV_TYPE&ads.is_lat=TIVOPLUS_DEV_LAT&ads.us_privacy=TIVOPLUS_USPRIVACY&ads.gdpr=&ads.gdpr_consent=&ads.app_domain=tivo.com&ads.device_type=TIVOPLUS_OPENRTB_DEVTYPE&ads.app_store_url=&ads.tivo_kvps=partnername%253DXumo%2526mvpd%253DTIVOPLUS_MVPD%2526adunittype%253DTIVOPLUS_ADUNIT_TYPE%2526sz%253D1920x1080%2526contenttype%253DLinear%2526uxloc%253DInapp%2526apptype%253DEntertainment%2526videotype%253Dmidroll%2526devcountry%253D%2526usid%253DTIVOPLUS_USERSESSION_ID%2526devlang%253D%2526platform%253DTIVOPLUS_PLATFORM%2526devmake%253DTIVOPLUS_DEVMAKE%2526devbrand%253D%2526devmake%253DTIVOPLUS_DEVMODEL%2526devmakedate%253D_ID%2526devlang%253D%2526platform%253DTIVOPLUS_PLATFORM%2526devmake%253DTIVOPLUS_DEVMAKE%2526devbrand%253D%2526devmake%253DTIVOPLUS_DEVMODEL%2526devmakedate%253D") | N26: 99000007 | P26: ✔
A27: 10426 | C27: XUMO
A28: 10427 | C28: XUMO
A29: 10428 | C29: XUMO
A30: 10429 | C30: XUMO
A31: 10430 | B31: Forensic Files | C31: XUMO | D31: Live | E31: 111976 | F31: 15836609091 | G31: 515581902 | J31: FORFLXU | K31: XUMO-Forensic Files | M31: https:TIVOPLUS_BLANK//db32be3yl2hko.cloudfront.net/11302/88885136/hls/master.m3u8?ads.xumo_channelId=88885136&ads.caid=ForensicFiles&ads.csid=tivo_ca_forensicfiles_ssai&ads.coppa=0&ads.provider_id=260&ads.content_producer_id=260&ads.content_producer=FilmRise&ads.content_network=FilmRise&ads.xumo_streamId=88885136&ads.content_length=&ads.content_language=en&ads.content_category=IAB17&ads.content_genre=Television&ads.content_rating=tv14&ads.content_channel=ForensicFiles&ads.app_name=TIVOPLUS_APPNAME&ads.app_version=TIVOPLUS_APP_VERSION&ads.app_bundle=tivo.entertainment&ads.did=TIVOPLUS_DEV_ID&ads.did_type=TIVOPLUS_DEV_TYPE&ads.is_lat=TIVOPLUS_DEV_LAT&ads.us_privacy=TIVOPLUS_USPRIVACY&ads.gdpr=&ads.gdpr_consent=&ads.app_domain=tivo.com&ads.device_type=TIVOPLUS_OPENRTB_DEVTYPE&ads.app_store_url=&ads.tivo_kvps=partnername%253DXumo%2526mvpd%253DTIVOPLUS_MVPD%2526adunittype%253DTIVOPLUS_ADUNIT_TYPE%2526sz%253D1920x1080%2526contenttype%253DLinear%2526uxloc%253DInapp%2526apptype%253DEntertainment%2526videotype%253Dmidroll%2526devcountry%253D%2526usid%253DTIVOPLUS_USERSESSION_ID%2526devlang%253D%2526platform%253DTIVOPLUS_PLATFORM%2526devmake%253DTIVOPLUS_DEVMAKE%2526devbrand%253D%2526devmake%253DTIVOPLUS_DEVMODEL%2526devmakedate%253D") | N31: 99000008 | P31: ✔
A32: 10431 | B32: Unsolved Mysteries | C32: XUMO | D32: Live | E32: 99303 | F32: 8319038138 | G32: 420272283 | J32: UNSLMYST | K32: XUMO-Unsolved Mysteries | M32: https:TIVOPLUS_BLANK//db32be3yl2hko.cloudfront.net/11302/88885018/hls/master.m3u8?ads.xumo_channelId=88885018&ads.caid=UnsolvedMysteries&ads.csid=tivo_unsolvedmysteries_ssai&ads.coppa=0&ads.provider_id=260&ads.content_producer_id=260&ads.content_producer=FilmRise&ads.content_network=FilmRise&ads.xumo_streamId=88885018&ads.content_length=&ads.content_language=en&ads.content_category=IAB17&ads.content_genre=Television&ads.content_rating=tv14&ads.content_channel=UnsolvedMyseries&ads.app_name=TIVOPLUS_APPNAME&ads.app_version=TIVOPLUS_APP_VERSION&ads.app_bundle=tivo.entertainment&ads.did=TIVOPLUS_DEV_ID&ads.did_type=TIVOPLUS_DEV_TYPE&ads.is_lat=TIVOPLUS_DEV_LAT&ads.us_privacy=TIVOPLUS_USPRIVACY&ads.gdpr=&ads.gdpr_consent=&ads.app_domain=tivo.com&ads.device_type=TIVOPLUS_OPENRTB_DEVTYPE&ads.app_store_url=&ads.tivo_kvps=partnername%253DXumo%2526mvpd%253DTIVOPLUS_MVPD%2526adunittype%253DTIVOPLUS_ADUNIT_TYPE%2526sz%253D1920x1080%2526contenttype%253DLinear%2526uxloc%253DInapp%2526apptype%253DEntertainment%2526videotype%253Dmidroll%2526devcountry%253D%2526usid%253DTIVOPLUS_USERSESSION_ID%2526devlang%253D%2526platform%253DTIVOPLUS_PLATFORM%2526devmake%253DTIVOPLUS_DEVMAKE%2526devbrand%253D%2526devmake%253DTIVOPLUS_DEVMODEL%2526devmakedate%253D | N32: 99000009 | P32: ✔
A33: 10432 | C33: XUMO
A34: 10433 | C34: XUMO
A35: 10434 | C35: XUMO
A36: 10435 | C36: XUMO
A37: 10436 | C37: XUMO
A38: 10437 | B38: Untold Stories of the ER | C38: XUMO | D38: Live | E38: 111987 | F38: 15836631635 | G38: 515581916 | J38: UNTSTORXU | K38: XUMO-Untold Stories of the ER | M38: https:TIVOPLUS_BLANK//db32be3yl2hko.cloudfront.net/11302/88885132/hls/master.m3u8?ads.xumo_channelId=88885132&ads.caid=FilmRise&ads.csid=tivo_us_untoldstoriesoftheer_ssai&ads.coppa=0&ads.provider_id=260&ads.content_producer_id=260&ads.content_producer=FilmRise&ads.content_network=FilmRise&ads.xumo_streamId=88885132&ads.content_length=&ads.content_language=en&ads.content_category=IAB17&ads.content_genre=Television&ads.content_rating=tv14&&ads.content_channel=UntoldStoriesOfTheER&ads.app_name=TIVOPLUS_APPNAME&ads.app_version=TIVOPLUS_APP_VERSION&ads.app_bundle=tivo.entertainment&ads.did=TIVOPLUS_DEV_ID&ads.did_type=TIVOPLUS_DEV_TYPE&ads.is_lat=TIVOPLUS_DEV_LAT&ads.us_privacy=TIVOPLUS_USPRIVACY&ads.gdpr=&ads.gdpr_consent=&ads.app_domain=tivo.com&ads.device_type=TIVOPLUS_OPENRTB_DEVTYPE&ads.app_store_url=&ads.tivo_kvps=partnername%253DXumo%2526mvpd%253DTIVOPLUS_MVPD%2526adunittype%253DTIVOPLUS_ADUNIT_TYPE%2526sz%253D1920x1080%2526contenttype%253DLinear%2526uxloc%253DInapp%2526apptype%253DEntertainment%2526videotype%253Dmidroll%2526devcountry%253D%2526usid%253DTIVOPLUS_USERSESSION_ID%2526devlang%253D%2526platform%253DTIVOPLUS_PLATFORM%2526devmake%253DTIVOPLUS_DEVMAKE%2526devbrand%253D%2526devmake%253DTIVOPLUS_DEVMODEL%2526devmakedate%253D | N38: 99000010 | P38: ✔
A39: 10438 | B39: Dr. G: Medical Examiner | C39: XUMO | D39: Live | E39: 111973 | F39: 15836593580 | G39: 515581899 | J39: DRGXU | K39: XUMO-Dr. G: Medical Examiner | M39: https:TIVOPLUS_BLANK//db32be3yl2hko.cloudfront.net/11302/88885124/hls/master.m3u8?ads.xumo_channelId=88885124&ads.caid=FilmRiseCA&ads.csid=tivo_ca_drgmedicalexaminer_ssai&ads.coppa=0&ads.provider_id=1082&ads.content_producer_id=1082&ads.content_producer=FilmRiseCA&ads.content_network=FilmRiseCA&ads.xumo_streamId=88885124&ads.content_length=&ads.content_language=en&ads.content_category=IAB17&ads.content_genre=Television&ads.content_rating=tv14&ads.content_channel=DrGMedicalExaminer&ads.app_name=TIVOPLUS_APPNAME&ads.app_version=TIVOPLUS_APP_VERSION&ads.app_bundle=tivo.entertainment&ads.did=TIVOPLUS_DEV_ID&ads.did_type=TIVOPLUS_DEV_TYPE&ads.is_lat=TIVOPLUS_DEV_LAT&ads.us_privacy=TIVOPLUS_USPRIVACY&ads.gdpr=&ads.gdpr_consent=&ads.app_domain=tivo.com&ads.device_type=TIVOPLUS_OPENRTB_DEVTYPE&ads.app_store_url=&ads.tivo_kvps=partnername%253DXumo%2526mvpd%253DTIVOPLUS_MVPD%2526adunittype%253DTIVOPLUS_ADUNIT_TYPE%2526sz%253D1920x1080%2526contenttype%253DLinear%2526uxloc%253DInapp%2526apptype%253DEntertainment%2526videotype%253Dmidroll%2526devcountry%253D%2526usid%253DTIVOPLUS_USERSESSION_ID%2526devlang%253D%2526platform%253DTIVOPLUS_PLATFORM%2526devmake%253DTIVOPLUS_DEVMAKE%2526devbrand%253D%2526devmake%253DTIVOPLUS_DEVMODEL%2526devmakedate%253D") | N39: 99000011 | P39: ✔
A40: 10439 | C40: XUMO
...

Sheet TMIS US
A1: Channel Number | B1: Channel Name | C1: Provider | D1: Availability | E1: Rovi 1.1 Source ID | F1: Rovi 2.0 Source ID | G1: Partner Station Id | H1: playbackUrlChannelId | I1: channelChangeId | J1: XUMO PlayURL | K1: TiVo+ Genre | L1: TMIS Platform (mATV) | M1: TMIS Unmanaged Streaming Devices
A2: 8101 | B2: CNN Headlines | C2: Pluto TV | D2: Live | E2: 100371 | F2: 9010079773 | G2: 427517053 | H2: cnn-headlines | I2: 5421f71da6af422839419cb3 | L2: ✔
A3: 8102 | B3: NBC News Now | C3: Pluto TV | D3: Live | E3: 100582 | F3: 9192516135 | G3: 429861982 | H3: nbc-news-now | I3: 5df97894467dfa00091c873c | L3: ✔
A4: 8103 | C4: Pluto TV
A5: 8104 | B5: CBS News 24/7 | C5: Pluto TV | D5: Live | E5: 100432 | F5: 9010105410 | G5: 427517050 | H5: cbs-news | I5: 5a6b92f6e22a617379789618 | L5: ✔
A6: 8105 | C6: Pluto TV
A7: 8106 | C7: Pluto TV
A8: 8107 | C8: Pluto TV
A9: 8108 | C9: Pluto TV
A10: 8109 | C10: Pluto TV
A11: 8110 | C11: Pluto TV
A12: 8111 | B12: Sky News | C12: Pluto TV | D12: Live | E12: 100417 | F12: 9010098841 | G12: 427517061 | H12: sky-news | I12: 55b285cd2665de274553d66f | L12: ✔
A13: 8112 | B13: Blaze Live | C13: Pluto TV | D13: Live | E13: 37159 | F13: 312864873 | G13: 235665557 | H13: blaze-live | I13: 5e46fba0c43b0d00096e5ac1 | L13: ✔
A14: 8113 | C14: Pluto TV
A15: 8114 | C15: Pluto TV
A16: 8115 | C16: Pluto TV
A17: 8116 | C17: Pluto TV
A18: 8117 | B18: Pluto TV Crime Movies | C18: Pluto TV | D18: Live | E18: 109771 | F18: 14580966827 | G18: 499315358 | H18: pluto-tv-crime-movies | I18: 5f4d8594eb979c0007706de7 | L18: ✔
A19: 8118 | B19: Pluto TV Westerns | C19: Pluto TV | D19: Live | E19: 100370 | F19: 9010079772 | G19: 427517072 | H19: pluto-tv-westerns-ptv1 | I19: 5b4e94282d4ec87bdcbb87cd | L19: ✔
A20: 8119 | B20: Pluto TV Action | C20: Pluto TV | D20: Live | E20: 100400 | F20: 9010089140 | G20: 427517024 | H20: pluto-tv-action | I20: 561d7d484dc7c8770484914a | L20: ✔
A21: 8120 | B21: Black Cinema | C21: Pluto TV | D21: Live | E21: 100364 | F21: 9010077077 | G21: 427517054 | H21: black-cinema | I21: 58af4c093a41ca9d4ecabe96 | L21: ✔
A22: 8121 | B22: Pluto TV Horror | C22: Pluto TV | D22: Live | E22: 100408 | F22: 9010092582 | G22: 427517034 | H22: pluto-tv-horror | I22: 569546031a619b8f07ce6e25 | L22: ✔
A23: 8122 | B23: Pluto TV Terror | C23: Pluto TV | D23: Live | E23: 100416 | F23: 9010098708 | G23: 427517019 | H23: pluto-tv-terror | I23: 5c6dc88fcd232425a6e0f06e | L23: ✔
A24: 8123 | B24: Pluto TV Sci-Fi | C24: Pluto TV | D24: Live | E24: 100413 | F24: 9010096138 | G24: 427517067 | H24: pluto-tv-sci-fi | I24: 5b4fc274694c027be6ed3eea | L24: ✔
A25: 8124 | B25: Pluto TV Comedy | C25: Pluto TV | D25: Live | E25: 100405 | F25: 9010089821 | G25: 427517068 | H25: pluto-tv-comedy | I25: 5a4d3a00ad95e4718ae8d8db | L25: ✔
A26: 8125 | B26: Pluto TV Drama | C26: Pluto TV | D26: Live | E26: 100406 | F26: 9010092184 | G26: 427517040 | H26: pluto-tv-drama | I26: 5b4e92e4694c027be6ecece1 | L26: ✔
A27: 8126 | B27: Pluto TV Fantastic | C27: Pluto TV | D27: Live | E27: 100407 | F27: 9010092350 | G27: 427517073 | H27: pluto-tv-fantastic | I27: 5b64a245a202b3337f09e51d | L27: ✔
A28: 8127 | C28: Pluto TV
A29: 8128 | B29: Pluto TV Romance | C29: Pluto TV | D29: Live | E29: 100412 | F29: 9010094694 | G29: 427571159 | H29: pluto-tv-romance | I29: 5a66795ef91fef2c7031c599 | L29: ✔
A30: 8129 | B30: Pluto TV Spotlight | C30: Pluto TV | D30: Live | E30: 100414 | F30: 9010098650 | G30: 427517026 | H30: pluto-tv-spotlight | I30: 5ba3fb9c4b078e0f37ad34e8 | L30: ✔
A31: 8130 | B31: Paramount Movie Channel | C31: Pluto TV | D31: Live | E31: 100399 | F31: 9010089139 | G31: 427517006 | H31: paramount-movie-channel | I31: 5cb0cae7a461406ffe3f5213 | L31: ✔
A32: 8131 | B32: 70's Cinema | C32: Pluto TV | D32: Live | E32: 101607 | F32: 10158522042 | G32: 442803426 | H32: 70s-cinema | I32: 5f4d878d3d19b30007d2e782 | L32: ✔
A33: 8132 | B33: 80's Rewind | C33: Pluto TV | D33: Live | E33: 101606 | F33: 10158517642 | G33: 442803415 | H33: 80s-rewind | I33: 5ca525b650be2571e3943c63 | L33: ✔
A34: 8133 | B34: 90's Throwback | C34: Pluto TV | D34: Live | E34: 101605 | F34: 10157721666 | G34: 442803411 | H34: 90s-throwback | I34: 5f4d86f519358a00072b978e | L34: ✔
A35: 8134 | C35: Pluto TV
A36: 8135 | C36: Pluto TV
A37: 8136 | C37: Pluto TV
A38: 8137 | C38: Pluto TV
A39: 8138 | B39: COPS | C39: Pluto TV | D39: Live | E39: 100375 | F39: 9010081021 | G39: 427517066 | H39: cops | I39: 5e1f7e089f23700009d66303 | L39: ✔
A40: 8139 | B40: Forensic Files | C40: Pluto TV | D40: Live | E40: 100380 | F40: 9010083617 | G40: 427517014 | H40: forensic-files | I40: 5bb1af6a268cae539bcedb0a | L40: ✔
...

Sheet TMIS CA
A1: Channel Number | B1: Channel Name | C1: Provider | D1: Availability | E1: Rovi 1.1 Source ID | F1: Rovi 2.0 Source ID | G1: Partner Station Id | H1: playbackUrlChannelId | I1: channelChangeId | J1: XUMO PlayURL | K1: TiVo+ Genre | L1: TMIS Platform (mATV) | M1: TMIS Unmanaged Streaming Devices
A2: 9001 | B2: Bloomberg TV | C2: Direct | D2: Live | E2: 113171 | F2: 16354099306 | G2: 521876205 | J2: https:TIVOPLUS_BLANK//dai.google.com/linear/hls/event/AshzBu9XTQScek7dcLQlCA/master.m3u8?devid=TIVOPLUS_DEV_ID&devlat=TIVOPLUS_DEV_LAT&gdprconsent=&platform=TIVOPLUS_PLATFORM | L2: ✔
A3: 9002 | B3: Bloomberg Originals | C3: Direct | D3: Live | E3: 113170 | F3: 16354087548 | G3: 521876204 | J3: https:TIVOPLUS_BLANK//dai.google.com/linear/hls/event/TgqE2Aw_SiKmXKQgJoVpJQ/master.m3u8?devid=TIVOPLUS_DEV_ID&devlat=TIVOPLUS_DEV_LAT&gdprconsent=&platform=TIVOPLUS_PLATFORM | L3: ✔
A4: 9003 | C4: XUMO
A5: 9004 | C5: XUMO
A6: 9005 | C6: XUMO
A7: 9006 | B7: Filmrise Canadien | C7: XUMO | D7: Live | E7: 111974 | F7: 15836602686 | G7: 515581920 | J7: https:TIVOPLUS_BLANK//db32be3yl2hko.cloudfront.net/11302/88885125/hls/master.m3u8?ads.xumo_channelId=88885125&ads.caid=FilmRiseCA&ads.csid=tivo_ca_filmrisecanadien_ssai&ads.coppa=0&ads.provider_id=1082&ads.content_producer_id=1082&ads.content_producer=FilmRiseCA&ads.content_network=FilmRiseCA&ads.xumo_streamId=88885125&ads.content_length=&ads.content_language=en&ads.content_category=IAB1-7&ads.content_genre=Television&ads.content_rating=tv14&&ads.content_channel=FilmriseCanadien&ads.app_name=TIVOPLUS_APPNAME&ads.app_version=TIVOPLUS_APP_VERSION&ads.app_bundle=tivo.entertainment&ads.did=TIVOPLUS_DEV_ID&ads.did_type=TIVOPLUS_DEV_TYPE&ads.is_lat=TIVOPLUS_DEV_LAT&ads.us_privacy=TIVOPLUS_USPRIVACY&ads.gdpr=&ads.gdpr_consent=&ads.app_domain=tivo.com&ads.device_type=TIVOPLUS_OPENRTB_DEVTYPE&ads.app_store_url=&ads.tivo_kvps=partnername%253DXumo%2526mvpd%253DTIVOPLUS_MVPD%2526adunittype%253DTIVOPLUS_ADUNIT_TYPE%2526sz%253D1920x1080%2526contenttype%253DLinear%2526uxloc%253DInapp%2526apptype%253DEntertainment%2526videotype%253Dmidroll%2526devcountry%253D%2526usid%253DTIVOPLUS_USERSESSION_ID%2526devlang%253D%2526platform%253DTIVOPLUS_PLATFORM%2526devmake%253DTIVOPLUS_DEVMAKE%2526devbrand%253D%2526devmake%253DTIVOPLUS_DEVMODEL%2526devmakedate%253D%2526devbrand%253D%2526devmake%253DTIVOPLUS_DEVMODEL%2526devmakedate%253D") | L7: ✔
A8: 9007 | C8: XUMO
A9: 9008 | C9: XUMO
A10: 9009 | C10: XUMO
A11: 9010 | C11: XUMO
A12: 9011 | B12: FilmRise Western | C12: XUMO | D12: Live | E12: 111975 | F12: 15836608730 | G12: 515581901 | J12: https:TIVOPLUS_BLANK//db32be3yl2hko.cloudfront.net/11302/88885127/hls/master.m3u8?ads.xumo_channelId=88885127&ads.caid=FilmRise&ads.csid=tivo_us_filmrisewestern_ssai&ads.coppa=0&ads.provider_id=260&ads.content_producer_id=260&ads.content_producer=FilmRise&ads.content_network=FilmRise&ads.xumo_streamId=88885127&ads.content_length=&ads.content_language=en&ads.content_category=IAB17&ads.content_genre=Television&ads.content_rating=tvpg&ads.content_channel=FilmriseWestern&ads.app_name=TIVOPLUS_APPNAME&ads.app_version=TIVOPLUS_APP_VERSION&ads.app_bundle=tivo.entertainment&ads.did=TIVOPLUS_DEV_ID&ads.did_type=TIVOPLUS_DEV_TYPE&ads.is_lat=TIVOPLUS_DEV_LAT&ads.us_privacy=TIVOPLUS_USPRIVACY&ads.gdpr=&ads.gdpr_consent=&ads.app_domain=tivo.com&ads.device_type=TIVOPLUS_OPENRTB_DEVTYPE&ads.app_store_url=&ads.tivo_kvps=partnername%253DXumo%2526mvpd%253DTIVOPLUS_MVPD%2526adunittype%253DTIVOPLUS_ADUNIT_TYPE%2526sz%253D1920x1080%2526contenttype%253DLinear%2526uxloc%253DIn-app%2526apptype%253DEntertainment%2526videotype%253Dmid-roll%2526devcountry%253D%2526usid%253DTIVOPLUS_USERSESSION_ID%2526devlang%253D%2526platform%253DTIVOPLUS_PLATFORM%2526devmake%253DTIVOPLUS_DEVMAKE%2526devbrand%253D%2526devmake%253DTIVOPLUS_DEVMODEL%2526devmakedate%253D | L12: ✔
A13: 9012 | C13: XUMO
A14: 9013 | C14: XUMO
A15: 9014 | C15: XUMO
A16: 9015 | C16: XUMO
A17: 9016 | C17: XUMO
A18: 9017 | B18: Shades of Black | C18: XUMO | D18: Live | E18: 112551 | F18: 16106044260 | G18: 519562724 | J18: https:TIVOPLUS_BLANK//db32be3yl2hko.cloudfront.net/11302/88885139/hls/playlist.m3u8?ads.xumo_channelId=88885139&ads.caid=FuseShadesofBlackCanada&ads.csid=tivo_ca_fuseshadesofblackcanada_ssai&ads.coppa=0&ads.provider_id=4032&ads.content_producer_id=4032&ads.content_producer=FuseShadesofBlackCanada&ads.content_network=FuseShadesofBlackCanada&ads.xumo_streamId=88885139&ads.content_length=&ads.content_language=en&ads.content_category=IAB1-7&ads.content_genre=Television&ads.content_rating=tv-14&ads.content_channel=ShadesofBlackCanada&ads.app_name=TIVOPLUS_APPNAME&ads.app_version=TIVOPLUS_APP_VERSION&ads.app_bundle=tivo.entertainment&ads.did=TIVOPLUS_DEV_ID&ads.did_type=TIVOPLUS_DEV_TYPE&ads.is_lat=TIVOPLUS_DEV_LAT&ads.us_privacy=TIVOPLUS_USPRIVACY&ads.gdpr=&ads.gdpr_consent=&ads.app_domain=tivo.com&ads.device_type=TIVOPLUS_OPENRTB_DEVTYPE&ads.app_store_url=&ads.tivo_kvps=partnername%253DXumo%2526mvpd%253DTIVOPLUS_MVPD%2526adunittype%253DTIVOPLUS_ADUNIT_TYPE%2526sz%253D1920x1080%2526contenttype%253DLinear%2526uxloc%253DIn-app%2526apptype%253DEntertainment%2526videotype%253Dmid-roll%2526devcountry%253D%2526usid%253DTIVOPLUS_USERSESSION_ID%2526devlang%253D%2526platform%253DTIVOPLUS_PLATFORM%2526devmake%253DTIVOPLUS_DEVMAKE%2526devbrand%253D%2526devmake%253DTIVOPLUS_DEVMODEL%2526devmakedate%253D | L18: ✔
A19: 9018 | B19: OUTtv Proud | C19: XUMO | D19: Live | E19: 112549 | F19: 16106021655 | G19: 519562723 | J19: https:TIVOPLUS_BLANK//db32be3yl2hko.cloudfront.net/11302/88885137/hls/playlist.m3u8?ads.xumo_channelId=88885137&ads.caid=FuseOutTVProud&ads.csid=tivo_us_fuseouttvproud_ssai&ads.coppa=0&ads.provider_id=4004&ads.content_producer_id=4004&ads.content_producer=FuseOutTVProud&ads.content_network=FuseOutTVProud&ads.xumo_streamId=88885137&ads.content_length=&ads.content_language=en&ads.content_category=IAB1-7&ads.content_genre=Television&ads.content_rating=tv-14&ads.content_channel=OutTVProud&ads.app_name=TIVOPLUS_APPNAME&ads.app_version=TIVOPLUS_APP_VERSION&ads.app_bundle=tivo.entertainment&ads.did=TIVOPLUS_DEV_ID&ads.did_type=TIVOPLUS_DEV_TYPE&ads.is_lat=TIVOPLUS_DEV_LAT&ads.us_privacy=TIVOPLUS_USPRIVACY&ads.gdpr=&ads.gdpr_consent=&ads.app_domain=tivo.com&ads.device_type=TIVOPLUS_OPENRTB_DEVTYPE&ads.app_store_url=&ads.tivo_kvps=partnername%253DXumo%2526mvpd%253DTIVOPLUS_MVPD%2526adunittype%253DTIVOPLUS_ADUNIT_TYPE%2526sz%253D1920x1080%2526contenttype%253DLinear%2526uxloc%253DIn-app%2526apptype%253DEntertainment%2526videotype%253Dmid-roll%2526devcountry%253D%2526usid%253DTIVOPLUS_USERSESSION_ID%2526devlang%253D%2526platform%253DTIVOPLUS_PLATFORM%2526devmake%253DTIVOPLUS_DEVMAKE%2526devbrand%253D%2526devmake%253DTIVOPLUS_DEVMODEL%2526devmakedate%253D | L19: ✔
A20: 9019 | C20: XUMO
A21: 9020 | C21: XUMO
A22: 9021 | C22: XUMO
A23: 9022 | C23: XUMO
A24: 9023 | C24: XUMO
A25: 9024 | B25: Filmrise Classic TV | C25: XUMO | D25: Live | E25: 109841 | F25: 14663826120 | G25: 500453464 | J25: https:TIVOPLUS_BLANK//db32be3yl2hko.cloudfront.net/11302/88885126/hls/master.m3u8?ads.xumo_channelId=88885126&ads.caid=FilmRiseCA&ads.csid=tivo_ca_filmriseclassictv_ssai&ads.coppa=0&ads.provider_id=1082&ads.content_producer_id=1082&ads.content_producer=FilmRiseCA&ads.content_network=FilmRiseCA&ads.xumo_streamId=88885126&ads.content_length=&ads.content_language=en&ads.content_category=IAB1-7&ads.content_genre=Television&ads.content_rating=tvpg&ads.content_channel=FilmriseClassicTV&ads.app_name=TIVOPLUS_APPNAME&ads.app_version=TIVOPLUS_APP_VERSION&ads.app_bundle=tivo.entertainment&ads.did=TIVOPLUS_DEV_ID&ads.did_type=TIVOPLUS_DEV_TYPE&ads.is_lat=TIVOPLUS_DEV_LAT&ads.us_privacy=TIVOPLUS_USPRIVACY&ads.gdpr=&ads.gdpr_consent=&ads.app_domain=tivo.com&ads.device_type=TIVOPLUS_OPENRTB_DEVTYPE&ads.app_store_url=&ads.tivo_kvps=partnername%253DXumo%2526mvpd%253DTIVOPLUS_MVPD%2526adunittype%253DTIVOPLUS_ADUNIT_TYPE%2526sz%253D1920x1080%2526contenttype%253DLinear%2526uxloc%253DIn-app%2526apptype%253DEntertainment%2526videotype%253Dmidroll%2526devcountry%253D%2526usid%253DTIVOPLUS_USERSESSION_ID%2526devlang%253D%2526platform%253DTIVOPLUS_PLATFORM%2526devmake%253DTIVOPLUS_DEVMAKE%2526devbrand%253D%2526devmake%253DTIVOPLUS_DEVMODEL%2526devmakedate%253D") | L25: ✔
A26: 9025 | B26: Hell’s Kitchen | C26: XUMO | D26: Live | E26: 111978 | F26: 15836622952 | G26: 515581914 | J26: https:TIVOPLUS_BLANK//db32be3yl2hko.cloudfront.net/11302/88885129/hls/master.m3u8?ads.xumo_channelId=88885129&ads.caid=FilmRise&ads.csid=tivo_us_hellskitchen_ssai&ads.coppa=0&ads.provider_id=260&ads.content_producer_id=260&ads.content_producer=FilmRise&ads.content_network=FilmRise&ads.xumo_streamId=88885129&ads.content_length=&ads.content_language=en&ads.content_category=IAB17&ads.content_genre=Television&ads.content_rating=tv14&ads.content_channel=HellsKitchen&ads.app_name=TIVOPLUS_APPNAME&ads.app_version=TIVOPLUS_APP_VERSION&ads.app_bundle=tivo.entertainment&ads.did=TIVOPLUS_DEV_ID&ads.did_type=TIVOPLUS_DEV_TYPE&ads.is_lat=TIVOPLUS_DEV_LAT&ads.us_privacy=TIVOPLUS_USPRIVACY&ads.gdpr=&ads.gdpr_consent=&ads.app_domain=tivo.com&ads.device_type=TIVOPLUS_OPENRTB_DEVTYPE&ads.app_store_url=&ads.tivo_kvps=partnername%253DXumo%2526mvpd%253DTIVOPLUS_MVPD%2526adunittype%253DTIVOPLUS_ADUNIT_TYPE%2526sz%253D1920x1080%2526contenttype%253DLinear%2526uxloc%253DInapp%2526apptype%253DEntertainment%2526videotype%253Dmidroll%2526devcountry%253D%2526usid%253DTIVOPLUS_USERSESSION_ID%2526devlang%253D%2526platform%253DTIVOPLUS_PLATFORM%2526devmake%253DTIVOPLUS_DEVMAKE%2526devbrand%253D%2526devmake%253DTIVOPLUS_DEVMODEL%2526devmakedate%253D_ID%2526devlang%253D%2526platform%253DTIVOPLUS_PLATFORM%2526devmake%253DTIVOPLUS_DEVMAKE%2526devbrand%253D%2526devmake%253DTIVOPLUS_DEVMODEL%2526devmakedate%253D") | L26: ✔
A27: 9026 | C27: XUMO
A28: 9027 | C28: XUMO
A29: 9028 | C29: XUMO
A30: 9029 | C30: XUMO
A31: 9030 | B31: Forensic Files | C31: XUMO | D31: Live | E31: 111976 | F31: 15836609091 | G31: 515581902 | J31: https:TIVOPLUS_BLANK//db32be3yl2hko.cloudfront.net/11302/88885136/hls/master.m3u8?ads.xumo_channelId=88885136&ads.caid=ForensicFiles&ads.csid=tivo_ca_forensicfiles_ssai&ads.coppa=0&ads.provider_id=260&ads.content_producer_id=260&ads.content_producer=FilmRise&ads.content_network=FilmRise&ads.xumo_streamId=88885136&ads.content_length=&ads.content_language=en&ads.content_category=IAB17&ads.content_genre=Television&ads.content_rating=tv14&ads.content_channel=ForensicFiles&ads.app_name=TIVOPLUS_APPNAME&ads.app_version=TIVOPLUS_APP_VERSION&ads.app_bundle=tivo.entertainment&ads.did=TIVOPLUS_DEV_ID&ads.did_type=TIVOPLUS_DEV_TYPE&ads.is_lat=TIVOPLUS_DEV_LAT&ads.us_privacy=TIVOPLUS_USPRIVACY&ads.gdpr=&ads.gdpr_consent=&ads.app_domain=tivo.com&ads.device_type=TIVOPLUS_OPENRTB_DEVTYPE&ads.app_store_url=&ads.tivo_kvps=partnername%253DXumo%2526mvpd%253DTIVOPLUS_MVPD%2526adunittype%253DTIVOPLUS_ADUNIT_TYPE%2526sz%253D1920x1080%2526contenttype%253DLinear%2526uxloc%253DInapp%2526apptype%253DEntertainment%2526videotype%253Dmidroll%2526devcountry%253D%2526usid%253DTIVOPLUS_USERSESSION_ID%2526devlang%253D%2526platform%253DTIVOPLUS_PLATFORM%2526devmake%253DTIVOPLUS_DEVMAKE%2526devbrand%253D%2526devmake%253DTIVOPLUS_DEVMODEL%2526devmakedate%253D") | L31: ✔
A32: 9031 | B32: Unsolved Mysteries | C32: XUMO | D32: Live | E32: 99303 | F32: 8319038138 | G32: 420272283 | J32: https:TIVOPLUS_BLANK//db32be3yl2hko.cloudfront.net/11302/88885018/hls/master.m3u8?ads.xumo_channelId=88885018&ads.caid=UnsolvedMysteries&ads.csid=tivo_unsolvedmysteries_ssai&ads.coppa=0&ads.provider_id=260&ads.content_producer_id=260&ads.content_producer=FilmRise&ads.content_network=FilmRise&ads.xumo_streamId=88885018&ads.content_length=&ads.content_language=en&ads.content_category=IAB17&ads.content_genre=Television&ads.content_rating=tv14&&ads.content_channel=UnsolvedMyseries&ads.app_name=TIVOPLUS_APPNAME&ads.app_version=TIVOPLUS_APP_VERSION&ads.app_bundle=tivo.entertainment&ads.did=TIVOPLUS_DEV_ID&ads.did_type=TIVOPLUS_DEV_TYPE&ads.is_lat=TIVOPLUS_DEV_LAT&ads.us_privacy=TIVOPLUS_USPRIVACY&ads.gdpr=&ads.gdpr_consent=&ads.app_domain=tivo.com&ads.device_type=TIVOPLUS_OPENRTB_DEVTYPE&ads.app_store_url=&ads.tivo_kvps=partnername%253DXumo%2526mvpd%253DTIVOPLUS_MVPD%2526adunittype%253DTIVOPLUS_ADUNIT_TYPE%2526sz%253D1920x1080%2526contenttype%253DLinear%2526uxloc%253DInapp%2526apptype%253DEntertainment%2526videotype%253Dmidroll%2526devcountry%253D%2526usid%253DTIVOPLUS_USERSESSION_ID%2526devlang%253D%2526platform%253DTIVOPLUS_PLATFORM%2526devmake%253DTIVOPLUS_DEVMAKE%2526devbrand%253D%2526devmake%253DTIVOPLUS_DEVMODEL%2526devmakedate%253D | L32: ✔
A33: 9032 | C33: XUMO
A34: 9033 | C34: XUMO
A35: 9034 | C35: XUMO
A36: 9035 | C36: XUMO
A37: 9036 | C37: XUMO
A38: 9037 | B38: Untold Stories of the ER | C38: XUMO | D38: Live | E38: 111987 | F38: 15836631635 | G38: 515581916 | J38: https:TIVOPLUS_BLANK//db32be3yl2hko.cloudfront.net/11302/88885132/hls/master.m3u8?ads.xumo_channelId=88885132&ads.caid=FilmRise&ads.csid=tivo_us_untoldstoriesoftheer_ssai&ads.coppa=0&ads.provider_id=260&ads.content_producer_id=260&ads.content_producer=FilmRise&ads.content_network=FilmRise&ads.xumo_streamId=88885132&ads.content_length=&ads.content_language=en&ads.content_category=IAB17&ads.content_genre=Television&ads.content_rating=tv14&&ads.content_channel=UntoldStoriesOfTheER&ads.app_name=TIVOPLUS_APPNAME&ads.app_version=TIVOPLUS_APP_VERSION&ads.app_bundle=tivo.entertainment&ads.did=TIVOPLUS_DEV_ID&ads.did_type=TIVOPLUS_DEV_TYPE&ads.is_lat=TIVOPLUS_DEV_LAT&ads.us_privacy=TIVOPLUS_USPRIVACY&ads.gdpr=&ads.gdpr_consent=&ads.app_domain=tivo.com&ads.device_type=TIVOPLUS_OPENRTB_DEVTYPE&ads.app_store_url=&ads.tivo_kvps=partnername%253DXumo%2526mvpd%253DTIVOPLUS_MVPD%2526adunittype%253DTIVOPLUS_ADUNIT_TYPE%2526sz%253D1920x1080%2526contenttype%253DLinear%2526uxloc%253DInapp%2526apptype%253DEntertainment%2526videotype%253Dmidroll%2526devcountry%253D%2526usid%253DTIVOPLUS_USERSESSION_ID%2526devlang%253D%2526platform%253DTIVOPLUS_PLATFORM%2526devmake%253DTIVOPLUS_DEVMAKE%2526devbrand%253D%2526devmake%253DTIVOPLUS_DEVMODEL%2526devmakedate%253D | L38: ✔
A39: 9038 | B39: Dr. G: Medical Examiner | C39: XUMO | D39: Live | E39: 111973 | F39: 15836593580 | G39: 515581899 | J39: https:TIVOPLUS_BLANK//db32be3yl2hko.cloudfront.net/11302/88885124/hls/master.m3u8?ads.xumo_channelId=88885124&ads.caid=FilmRiseCA&ads.csid=tivo_ca_drgmedicalexaminer_ssai&ads.coppa=0&ads.provider_id=1082&ads.content_producer_id=1082&ads.content_producer=FilmRiseCA&ads.content_network=FilmRiseCA&ads.xumo_streamId=88885124&ads.content_length=&ads.content_language=en&ads.content_category=IAB17&ads.content_genre=Television&ads.content_rating=tv14&ads.content_channel=DrGMedicalExaminer&ads.app_name=TIVOPLUS_APPNAME&ads.app_version=TIVOPLUS_APP_VERSION&ads.app_bundle=tivo.entertainment&ads.did=TIVOPLUS_DEV_ID&ads.did_type=TIVOPLUS_DEV_TYPE&ads.is_lat=TIVOPLUS_DEV_LAT&ads.us_privacy=TIVOPLUS_USPRIVACY&ads.gdpr=&ads.gdpr_consent=&ads.app_domain=tivo.com&ads.device_type=TIVOPLUS_OPENRTB_DEVTYPE&ads.app_store_url=&ads.tivo_kvps=partnername%253DXumo%2526mvpd%253DTIVOPLUS_MVPD%2526adunittype%253DTIVOPLUS_ADUNIT_TYPE%2526sz%253D1920x1080%2526contenttype%253DLinear%2526uxloc%253DInapp%2526apptype%253DEntertainment%2526videotype%253Dmidroll%2526devcountry%253D%2526usid%253DTIVOPLUS_USERSESSION_ID%2526devlang%253D%2526platform%253DTIVOPLUS_PLATFORM%2526devmake%253DTIVOPLUS_DEVMAKE%2526devbrand%253D%2526devmake%253DTIVOPLUS_DEVMODEL%2526devmakedate%253D") | L39: ✔
A40: 9039 | C40: XUMO
...

Sheet operator_config
A1: operator_name | B1: operator_id | C1: region | D1: start_channel | E1: start_channel_offset | F1: lineup_size | G1: xumo_partner_id | H1: plutotv_range | I1: xumo_range | J1: plex_range | K1: mso_service_ids | L1: alt_name
A2: Eastlink | B2: tivo:pt.5161 | C2: CA | D2: 2500 | E2: 400 | F2: 1400 | G2: 1007769 | I2: 2901 | J2: 3201
A3: Mediacom-Dev | B3: tivo:pt.5163 | C3: US | D3: 3101 | E3: 100 | F3: 1400 | G3: 1007720 | H3: 3201 | I3: 3502 | J3: 3802
A4: Secv | B4: tivo:pt.5057 | C4: US | D4: 1056 | E4: 100 | F4: 1400 | G4: 1007713 | H4: 1157 | I4: 1457 | J4: 1757
A5: Blue Ridge-Dev | B5: tivo:pt.5174 | C5: US | D5: 2000 | E5: 100 | F5: 1400 | G5: 1007767 | H5: 2101 | I5: 2401 | J5: 2701
A6: Cincinnati Bell | B6: tivo:pt.5199 | C6: US | D6: 1000 | E6: 100 | F6: 1400 | G6: 1007707 | H6: 1101 | I6: 1401 | J6: 1701 | L6: altafiber
A7: Cincinnati Bell-Dev | B7: tivo:pt.5202 | C7: US | D7: 1000 | E7: 100 | F7: 1400 | G7: 1007706 | H7: 1101 | I7: 1401 | J7: 1701 | L7: altafiber
A8: SECV-DEV | B8: tivo:pt.5211 | C8: US | D8: 1056 | E8: 100 | F8: 1400 | G8: 1007712 | H8: 1157 | I8: 1457 | J8: 1757
A9: Atlantic Broadband | B9: tivo:pt.4400 | C9: US | D9: 2000 | E9: 100 | F9: 1400 | G9: 1007725 | H9: 2101 | I9: 2401 | J9: 2701 | L9: Breezeline
A10: Blue Stream-Dev | B10: tivo:pt.5221 | C10: US | D10: 1000 | E10: 100 | F10: 1400 | G10: 1007705 | H10: 1101 | I10: 1401 | J10: 1701
A11: BlueStream | B11: tivo:pt.5220 | C11: US | D11: 1000 | E11: 100 | F11: 1400 | G11: 1007704 | H11: 1101 | I11: 1401 | J11: 1701
A12: Armstrong - Dev | B12: tivo:pt.5230 | C12: US | D12: 1000 | E12: 100 | F12: 1400 | G12: 1007768 | H12: 1101 | I12: 1401 | J12: 1701
A13: midco | B13: tivo:pt.4203 | C13: US | D13: 3000 | E13: 100 | F13: 1400 | G13: 1007163 | H13: 3101 | I13: 3401 | J13: 3701
A14: Hotwire-Dev | B14: tivo:pt.5315 | C14: US | D14: 10000 | E14: 100 | F14: 1400 | G14: 1007709 | H14: 10101 | I14: 10401 | J14: 10701
A15: astound | B15: tivo:pt.4616 | C15: US | D15: 2000 | E15: 100 | F15: 1400 | G15: 1007703 | H15: 2101 | I15: 2401
A16: Hotwire | B16: tivo:pt.5314 | C16: US | D16: 10000 | E16: 100 | F16: 1400 | G16: 1007714 | H16: 10101 | I16: 10401 | J16: 10701
A17: Blue Ridge | B17: tivo:pt.4486 | C17: US | D17: 2000 | E17: 100 | F17: 1400 | G17: 1007776 | H17: 2101 | I17: 2401 | J17: 2701
A18: Mediacom | B18: tivo:pt.4177 | C18: US | D18: 3101 | E18: 100 | F18: 1400 | G18: 1007721 | H18: 3202 | I18: 3502 | J18: 3802
A19: Armstrong | B19: tivo:pt.4618 | C19: US | D19: 1000 | E19: 100 | F19: 1400 | G19: 1007769 | H19: 1101 | I19: 1401 | J19: 1701
A20: CableCo11 | B20: tivo:pt.5051 | C20: US | D20: 11400 | E20: 100 | F20: 1400 | G20: 1007998 | H20: 11501 | I20: 11801 | J20: 12101
A21: Astound-Dev | C21: US | E21: 100 | F21: 1400
A22: CableCo3 | C22: US | E22: 100 | F22: 1400
A23: Midoco-Dev | C23: US | E23: 100 | F23: 1400
A24: Eastlink-Dev | C24: CA | E24: 100 | F24: 1400
A25: Atlantic Broadband Dev | C25: US | E25: 100 | F25: 1400 | L25: Breezeline
A26: TMIS US | B26: tmis_us | C26: US | D26: 8000 | E26: 100 | F26: 2000
A27: TMIS CA | B27: tmis_ca | C27: CA | D27: 8000 | E27: 100 | F27: 2000

Sheet Ch_Add_Remove_Alert
A1: Row | B1: Txt | C1: Total_Audit_Flag | D1: Column1
A2: 1 | B2: Total Channels That need attention!! | C2: =E2+G2 -> 0 | D2: Total Channels ADDED that need to be resolved | E2: =SUM(B3:B6) -> 0 | F2: Total Channels REMOVED that need to be resolved | G2: =SUM(D3:D6) -> 0 | I2: IPTV-SA Created:9/23/2025
A3: IPTV US Added - unresolved | B3: =COUNTIF(E11:E100004,"Please Notify - Channel Added") -> 0 | C3: IPTV US Removed - unresolved | D3: =COUNTIF(D11:D100004,"Please Notify - Channel Removed") -> 0 | E3: IPTV US Total Changes | F3: =B3+D3 -> 0
A4: IPTV CA Added - unresolved | B4: =COUNTIF(K11:K100004,"Please Notify - Channel Added") -> 0 | C4: IPTV CA Removed - unresolved | D4: =COUNTIF(J11:J100004,"Please Notify - Channel Removed") -> 0 | E4: IPTV CA Total Changes | F4: =B4+D4 -> 0
A5: TMIS US Added- unresolved | B5: =COUNTIF(Q11:Q100004,"Please Notify - Channel Added") -> 0 | C5: TMIS US Removed - unresolved | D5: =COUNTIF(P11:P100004,"Please Notify - Channel Removed") -> 0 | E5: TMIS US Total Changes | F5: =B5+D5 -> 0
A6: TMIS CA Added- unresolved | B6: =COUNTIF(W11:W100004,"Please Notify - Channel Added") -> 0 | C6: TMIS CA Removed - unresolved | D6: =COUNTIF(V11:V100004,"Please Notify - Channel Removed") -> 0 | E6: TMIS CA Total Changes | F6: =B6+D6 -> 0
A8: Customer Success Usage ONLY. Do not modify unless you speak with Hayley - hayley.fletcher@xperi.com. This sheet is used to flag changes to the master. If there are any pending notifications, an email will be sent with the report. Once customers have been notified, please update the "State." Example, if "Please Notify" is set for Removed_Notified, then after customer have been notified change the state of the channel to Vacant to resolve it. Likewise, if the Add_Notified is set to "Please Notify" then udate the State to "Active" to resolve the fact that it is now in use.
A10: IPTV_US_Ch_Num | B10: IPTV_US_Ch_Name | C10: IPTV_US_Ch_State | D10: IPTV_US_Removed | E10: IPTV_US_Ch_Add | F10: _....._ | G10: IPTV_CA_Ch_Num | H10: IPTV_CA_Ch_Name | I10: IPTV_CA_Ch_State | J10: IPTV_CA_Removed | K10: IPTV_CA_Add | L10: ___----____ | M10: TMIS_US_Ch_Num | N10: TMIS_US_Ch_Name | O10: TMIS_US_Ch_State | P10: TMIS_US_Removed | Q10: TMIS_US_Ch_Add | R10: _....._2 | S10: TMIS_CA_Ch_Num | T10: TMIS_CA_Ch_Name | U10: TMIS_CA_Ch_State | V10: TMIS_CA_Removed | W10: TMIS_CA_Add
A11: ='IPTV US'!A2 -> 10101 | B11: =T('IPTV US'!B2) -> CNN Headlines | C11: Active | D11: =IF(C11="Active",IF(B11="","Please Notify - Channel Removed",""),"") | E11: =IF(C11="Vacant",IF(B11="","","Please Notify - Channel Added"),"") | F11: - | G11: ='IPTV CA'!A2 -> 10401 | H11: =T('IPTV CA'!B2) -> Bloomberg TV | I11: Active | J11: =IF(I11="Active",IF(H11="","Please Notify - Channel Removed",""),"") | K11: =IF(I11="Vacant",IF(H11="","","Please Notify - Channel Added"),"") | M11: ='TMIS US'!A2 -> 8101 | N11: =T('TMIS US'!B2) -> CNN Headlines | O11: Active | P11: =IF(O11="Active",IF(N11="","Please Notify - Channel Removed",""),"") | Q11: =IF(O11="Vacant",IF(N11="","","Please Notify - Channel Added"),"") | S11: ='TMIS CA'!A2 -> 9001 | T11: =T('TMIS CA'!B2) -> Bloomberg TV | U11: Active | V11: =IF(U11="Active",IF(T11="","Please Notify - Channel Removed",""),"") | W11: =IF(U11="Vacant",IF(T11="","","Please Notify - Channel Added"),"")
A12: ='IPTV US'!A3 -> 10102 | B12: =T('IPTV US'!B3) -> NBC News Now | C12: Active | D12: =IF(C12="Active",IF(B12="","Please Notify - Channel Removed",""),"") | E12: =IF(C12="Vacant",IF(B12="","","Please Notify - Channel Added"),"") | F12: - | G12: ='IPTV CA'!A3 -> 10402 | H12: =T('IPTV CA'!B3) -> Bloomberg Originals | I12: Active | J12: =IF(I12="Active",IF(H12="","Please Notify - Channel Removed",""),"") | K12: =IF(I12="Vacant",IF(H12="","","Please Notify - Channel Added"),"") | M12: ='TMIS US'!A3 -> 8102 | N12: =T('TMIS US'!B3) -> NBC News Now | O12: Active | P12: =IF(O12="Active",IF(N12="","Please Notify - Channel Removed",""),"") | Q12: =IF(O12="Vacant",IF(N12="","","Please Notify - Channel Added"),"") | S12: ='TMIS CA'!A3 -> 9002 | T12: =T('TMIS CA'!B3) -> Bloomberg Originals | U12: Active | V12: =IF(U12="Active",IF(T12="","Please Notify - Channel Removed",""),"") | W12: =IF(U12="Vacant",IF(T12="","","Please Notify - Channel Added"),"")
A13: ='IPTV US'!A4 -> 10103 | B13: =T('IPTV US'!B4) | C13: Vacant | D13: =IF(C13="Active",IF(B13="","Please Notify - Channel Removed",""),"") | E13: =IF(C13="Vacant",IF(B13="","","Please Notify - Channel Added"),"") | F13: - | G13: ='IPTV CA'!A4 -> 10403 | H13: =T('IPTV CA'!B4) | I13: Vacant | J13: =IF(I13="Active",IF(H13="","Please Notify - Channel Removed",""),"") | K13: =IF(I13="Vacant",IF(H13="","","Please Notify - Channel Added"),"") | M13: ='TMIS US'!A4 -> 8103 | N13: =T('TMIS US'!B4) | O13: Vacant | P13: =IF(O13="Active",IF(N13="","Please Notify - Channel Removed",""),"") | Q13: =IF(O13="Vacant",IF(N13="","","Please Notify - Channel Added"),"") | S13: ='TMIS CA'!A4 -> 9003 | T13: =T('TMIS CA'!B4) | U13: Vacant | V13: =IF(U13="Active",IF(T13="","Please Notify - Channel Removed",""),"") | W13: =IF(U13="Vacant",IF(T13="","","Please Notify - Channel Added"),"")
A14: ='IPTV US'!A5 -> 10104 | B14: =T('IPTV US'!B5) -> CBS News 24/7 | C14: Active | D14: =IF(C14="Active",IF(B14="","Please Notify - Channel Removed",""),"") | E14: =IF(C14="Vacant",IF(B14="","","Please Notify - Channel Added"),"") | F14: - | G14: ='IPTV CA'!A5 -> 10404 | H14: =T('IPTV CA'!B5) | I14: Vacant | J14: =IF(I14="Active",IF(H14="","Please Notify - Channel Removed",""),"") | K14: =IF(I14="Vacant",IF(H14="","","Please Notify - Channel Added"),"") | M14: ='TMIS US'!A5 -> 8104 | N14: =T('TMIS US'!B5) -> CBS News 24/7 | O14: Active | P14: =IF(O14="Active",IF(N14="","Please Notify - Channel Removed",""),"") | Q14: =IF(O14="Vacant",IF(N14="","","Please Notify - Channel Added"),"") | S14: ='TMIS CA'!A5 -> 9004 | T14: =T('TMIS CA'!B5) | U14: Vacant | V14: =IF(U14="Active",IF(T14="","Please Notify - Channel Removed",""),"") | W14: =IF(U14="Vacant",IF(T14="","","Please Notify - Channel Added"),"")
A15: ='IPTV US'!A6 -> 10105 | B15: =T('IPTV US'!B6) | C15: Vacant | D15: =IF(C15="Active",IF(B15="","Please Notify - Channel Removed",""),"") | E15: =IF(C15="Vacant",IF(B15="","","Please Notify - Channel Added"),"") | F15: - | G15: ='IPTV CA'!A6 -> 10405 | H15: =T('IPTV CA'!B6) | I15: Vacant | J15: =IF(I15="Active",IF(H15="","Please Notify - Channel Removed",""),"") | K15: =IF(I15="Vacant",IF(H15="","","Please Notify - Channel Added"),"") | M15: ='TMIS US'!A6 -> 8105 | N15: =T('TMIS US'!B6) | O15: Vacant | P15: =IF(O15="Active",IF(N15="","Please Notify - Channel Removed",""),"") | Q15: =IF(O15="Vacant",IF(N15="","","Please Notify - Channel Added"),"") | S15: ='TMIS CA'!A6 -> 9005 | T15: =T('TMIS CA'!B6) | U15: Vacant | V15: =IF(U15="Active",IF(T15="","Please Notify - Channel Removed",""),"") | W15: =IF(U15="Vacant",IF(T15="","","Please Notify - Channel Added"),"")
A16: ='IPTV US'!A7 -> 10106 | B16: =T('IPTV US'!B7) | C16: Vacant | D16: =IF(C16="Active",IF(B16="","Please Notify - Channel Removed",""),"") | E16: =IF(C16="Vacant",IF(B16="","","Please Notify - Channel Added"),"") | F16: - | G16: ='IPTV CA'!A7 -> 10406 | H16: =T('IPTV CA'!B7) -> Filmrise Canadien | I16: Active | J16: =IF(I16="Active",IF(H16="","Please Notify - Channel Removed",""),"") | K16: =IF(I16="Vacant",IF(H16="","","Please Notify - Channel Added"),"") | M16: ='TMIS US'!A7 -> 8106 | N16: =T('TMIS US'!B7) | O16: Vacant | P16: =IF(O16="Active",IF(N16="","Please Notify - Channel Removed",""),"") | Q16: =IF(O16="Vacant",IF(N16="","","Please Notify - Channel Added"),"") | S16: ='TMIS CA'!A7 -> 9006 | T16: =T('TMIS CA'!B7) -> Filmrise Canadien | U16: Active | V16: =IF(U16="Active",IF(T16="","Please Notify - Channel Removed",""),"") | W16: =IF(U16="Vacant",IF(T16="","","Please Notify - Channel Added"),"")
A17: ='IPTV US'!A8 -> 10107 | B17: =T('IPTV US'!B8) | C17: Vacant | D17: =IF(C17="Active",IF(B17="","Please Notify - Channel Removed",""),"") | E17: =IF(C17="Vacant",IF(B17="","","Please Notify - Channel Added"),"") | F17: - | G17: ='IPTV CA'!A8 -> 10407 | H17: =T('IPTV CA'!B8) | I17: Vacant | J17: =IF(I17="Active",IF(H17="","Please Notify - Channel Removed",""),"") | K17: =IF(I17="Vacant",IF(H17="","","Please Notify - Channel Added"),"") | M17: ='TMIS US'!A8 -> 8107 | N17: =T('TMIS US'!B8) | O17: Vacant | P17: =IF(O17="Active",IF(N17="","Please Notify - Channel Removed",""),"") | Q17: =IF(O17="Vacant",IF(N17="","","Please Notify - Channel Added"),"") | S17: ='TMIS CA'!A8 -> 9007 | T17: =T('TMIS CA'!B8) | U17: Vacant | V17: =IF(U17="Active",IF(T17="","Please Notify - Channel Removed",""),"") | W17: =IF(U17="Vacant",IF(T17="","","Please Notify - Channel Added"),"")
A18: ='IPTV US'!A9 -> 10108 | B18: =T('IPTV US'!B9) | C18: Vacant | D18: =IF(C18="Active",IF(B18="","Please Notify - Channel Removed",""),"") | E18: =IF(C18="Vacant",IF(B18="","","Please Notify - Channel Added"),"") | F18: - | G18: ='IPTV CA'!A9 -> 10408 | H18: =T('IPTV CA'!B9) | I18: Vacant | J18: =IF(I18="Active",IF(H18="","Please Notify - Channel Removed",""),"") | K18: =IF(I18="Vacant",IF(H18="","","Please Notify - Channel Added"),"") | M18: ='TMIS US'!A9 -> 8108 | N18: =T('TMIS US'!B9) | O18: Vacant | P18: =IF(O18="Active",IF(N18="","Please Notify - Channel Removed",""),"") | Q18: =IF(O18="Vacant",IF(N18="","","Please Notify - Channel Added"),"") | S18: ='TMIS CA'!A9 -> 9008 | T18: =T('TMIS CA'!B9) | U18: Vacant | V18: =IF(U18="Active",IF(T18="","Please Notify - Channel Removed",""),"") | W18: =IF(U18="Vacant",IF(T18="","","Please Notify - Channel Added"),"")
A19: ='IPTV US'!A10 -> 10109 | B19: =T('IPTV US'!B10) | C19: Vacant | D19: =IF(C19="Active",IF(B19="","Please Notify - Channel Removed",""),"") | E19: =IF(C19="Vacant",IF(B19="","","Please Notify - Channel Added"),"") | F19: - | G19: ='IPTV CA'!A10 -> 10409 | H19: =T('IPTV CA'!B10) | I19: Vacant | J19: =IF(I19="Active",IF(H19="","Please Notify - Channel Removed",""),"") | K19: =IF(I19="Vacant",IF(H19="","","Please Notify - Channel Added"),"") | M19: ='TMIS US'!A10 -> 8109 | N19: =T('TMIS US'!B10) | O19: Vacant | P19: =IF(O19="Active",IF(N19="","Please Notify - Channel Removed",""),"") | Q19: =IF(O19="Vacant",IF(N19="","","Please Notify - Channel Added"),"") | S19: ='TMIS CA'!A10 -> 9009 | T19: =T('TMIS CA'!B10) | U19: Vacant | V19: =IF(U19="Active",IF(T19="","Please Notify - Channel Removed",""),"") | W19: =IF(U19="Vacant",IF(T19="","","Please Notify - Channel Added"),"")
A20: ='IPTV US'!A11 -> 10110 | B20: =T('IPTV US'!B11) | C20: Vacant | D20: =IF(C20="Active",IF(B20="","Please Notify - Channel Removed",""),"") | E20: =IF(C20="Vacant",IF(B20="","","Please Notify - Channel Added"),"") | F20: - | G20: ='IPTV CA'!A11 -> 10410 | H20: =T('IPTV CA'!B11) | I20: Vacant | J20: =IF(I20="Active",IF(H20="","Please Notify - Channel Removed",""),"") | K20: =IF(I20="Vacant",IF(H20="","","Please Notify - Channel Added"),"") | M20: ='TMIS US'!A11 -> 8110 | N20: =T('TMIS US'!B11) | O20: Vacant | P20: =IF(O20="Active",IF(N20="","Please Notify - Channel Removed",""),"") | Q20: =IF(O20="Vacant",IF(N20="","","Please Notify - Channel Added"),"") | S20: ='TMIS CA'!A11 -> 9010 | T20: =T('TMIS CA'!B11) | U20: Vacant | V20: =IF(U20="Active",IF(T20="","Please Notify - Channel Removed",""),"") | W20: =IF(U20="Vacant",IF(T20="","","Please Notify - Channel Added"),"")
A21: ='IPTV US'!A12 -> 10111 | B21: =T('IPTV US'!B12) -> Sky News | C21: Active | D21: =IF(C21="Active",IF(B21="","Please Notify - Channel Removed",""),"") | E21: =IF(C21="Vacant",IF(B21="","","Please Notify - Channel Added"),"") | F21: - | G21: ='IPTV CA'!A12 -> 10411 | H21: =T('IPTV CA'!B12) -> FilmRise Western | I21: Active | J21: =IF(I21="Active",IF(H21="","Please Notify - Channel Removed",""),"") | K21: =IF(I21="Vacant",IF(H21="","","Please Notify - Channel Added"),"") | M21: ='TMIS US'!A12 -> 8111 | N21: =T('TMIS US'!B12) -> Sky News | O21: Active | P21: =IF(O21="Active",IF(N21="","Please Notify - Channel Removed",""),"") | Q21: =IF(O21="Vacant",IF(N21="","","Please Notify - Channel Added"),"") | S21: ='TMIS CA'!A12 -> 9011 | T21: =T('TMIS CA'!B12) -> FilmRise Western | U21: Active | V21: =IF(U21="Active",IF(T21="","Please Notify - Channel Removed",""),"") | W21: =IF(U21="Vacant",IF(T21="","","Please Notify - Channel Added"),"")
A22: ='IPTV US'!A13 -> 10112 | B22: =T('IPTV US'!B13) -> Blaze Live | C22: Active | D22: =IF(C22="Active",IF(B22="","Please Notify - Channel Removed",""),"") | E22: =IF(C22="Vacant",IF(B22="","","Please Notify - Channel Added"),"") | F22: - | G22: ='IPTV CA'!A13 -> 10412 | H22: =T('IPTV CA'!B13) | I22: Vacant | J22: =IF(I22="Active",IF(H22="","Please Notify - Channel Removed",""),"") | K22: =IF(I22="Vacant",IF(H22="","","Please Notify - Channel Added"),"") | M22: ='TMIS US'!A13 -> 8112 | N22: =T('TMIS US'!B13) -> Blaze Live | O22: Active | P22: =IF(O22="Active",IF(N22="","Please Notify - Channel Removed",""),"") | Q22: =IF(O22="Vacant",IF(N22="","","Please Notify - Channel Added"),"") | S22: ='TMIS CA'!A13 -> 9012 | T22: =T('TMIS CA'!B13) | U22: Vacant | V22: =IF(U22="Active",IF(T22="","Please Notify - Channel Removed",""),"") | W22: =IF(U22="Vacant",IF(T22="","","Please Notify - Channel Added"),"")
